<?xml version="1.0"?>

<sdf version='1.7'>
  <model name='amr'>
    <link name='base_footprint'>
      <inertial>
        <pose>0 0 0.000106 0 0 0</pose>
        <mass>118.124</mass>
        <inertia>
          <ixx>11.5539</ixx>
          <ixy>-0.006658</ixy>
          <ixz>0</ixz>
          <iyy>4.68462</iyy>
          <iyz>0</iyz>
          <izz>15.748</izz>
        </inertia>
      </inertial>
      <collision name='base_footprint_fixed_joint_lump__base_link_collision'>
        <pose>0 0 0 0 0 0</pose>
        <geometry>
          <mesh>
            <scale>1 1 1</scale>
            <uri>model://amr/meshes/base_link.stl</uri>
          </mesh>
        </geometry>
      </collision>
      <collision name='base_footprint_fixed_joint_lump__laser_link_collision_1'>
        <pose>0 0 0.125 0 0 0</pose>
        <geometry>
          <mesh>
            <scale>1 1 1</scale>
            <uri>model://amr/meshes/rpi_lidar_1.stl</uri>
          </mesh>
        </geometry>
        <surface>
          <contact>
            <ode/>
          </contact>
          <friction>
            <ode/>
          </friction>
        </surface>
      </collision>
      <visual name='base_footprint_fixed_joint_lump__base_link_visual'>
        <pose>0 0 0 0 0 0</pose>
        <geometry>
          <mesh>
            <scale>1 1 1</scale>
            <uri>model://amr/meshes/base_link.stl</uri>
          </mesh>
        </geometry>
      </visual>
      <visual name='base_footprint_fixed_joint_lump__laser_link_visual_1'>
        <pose>0 0 0.125 0 0 0</pose>
        <geometry>
          <mesh>
            <scale>1 1 1</scale>
            <uri>model://amr/meshes/rpi_lidar_1.stl</uri>
          </mesh>
        </geometry>
        <material>
          <ambient>0 0 0 1</ambient>
          <diffuse>0 0 0 1</diffuse>
          <specular>0 0 0 1</specular>
          <emissive>0 0 0 0</emissive>
        </material>
      </visual>
      <gravity>1</gravity>
      <sensor name='imu_sensor' type='imu'>
        <pose>0 0 0 0 0 0</pose>
      </sensor>
      <pose>0 0 0 0 0 0</pose>
      <sensor name='laser_link_head_hokuyo_sensor' type='ray'>
        <always_on>1</always_on>
        <update_rate>10</update_rate>
        <visualize>1</visualize>
        <ray>
          <scan>
            <horizontal>
              <samples>360</samples>
              <resolution>1</resolution>
              <min_angle>-3.1416</min_angle>
              <max_angle>3.1416</max_angle>
            </horizontal>
          </scan>
          <range>
            <min>0.21</min>
            <max>5.5</max>
            <resolution>0.01</resolution>
          </range>
        </ray>
        <plugin name='laser_link_gazebo_ros_head_hokuyo_controller' filename='libgazebo_ros_ray_sensor.so'>
          <ros>
            <remapping>~/out:=scan</remapping>
          </ros>
          <output_type>sensor_msgs/LaserScan</output_type>
          <alwaysOn>1</alwaysOn>
          <updateRate>10</updateRate>
          <topicName>scan</topicName>
          <frame_name>laser_link</frame_name>
          <output_type>sensor_msgs/LaserScan</output_type>
        </plugin>
        <pose>0 0 0.125 0 0 0</pose>
      </sensor>
      <always_on>1</always_on>
      <update_rate>100</update_rate>
      <visualize>1</visualize>
      <topic>__default_topic__</topic>
      <plugin filename='libgazebo_ros_imu_sensor.so' name='imu_plugin'>
        <ros>
          <remapping>~/out:=imu/data</remapping>
        </ros>
        <topicName>imu/data</topicName>
        <updateRateHZ>10.0</updateRateHZ>
        <gaussianNoise>0.0</gaussianNoise>
        <initialOrientationAsReference>0</initialOrientationAsReference>
        <bodyName>base_footprint</bodyName>
        <frameName>base_footprint</frameName>
        <xyzOffset>0 0 0</xyzOffset>
        <rpyOffset>0 -0 0</rpyOffset>
        <!--<ignition::corrected_offsets>1</ignition::corrected_offsets>-->
      </plugin>
    </link>
    <joint name='front_left_wheel_joint' type='revolute'>
      <pose relative_to='base_footprint'>-0.265 0.28 0 0 0 0</pose>
      <parent>base_footprint</parent>
      <child>front_left_wheel_link</child>
      <axis>
        <xyz>0 1 0</xyz>
        <limit>
          <lower>-1e+16</lower>
          <upper>1e+16</upper>
        </limit>
        <dynamics>
          <spring_reference>0</spring_reference>
          <spring_stiffness>0</spring_stiffness>
        </dynamics>
      </axis>
    </joint>
    <link name='front_left_wheel_link'>
      <pose relative_to='front_left_wheel_joint'>0 0 0 0 0 0</pose>
      <inertial>
        <pose>0 0 0 0 -0 0</pose>
        <mass>1</mass>
        <inertia>
          <ixx>0.01024</ixx>
          <ixy>0</ixy>
          <ixz>0</ixz>
          <iyy>0.01024</iyy>
          <iyz>0</iyz>
          <izz>0.01024</izz>
        </inertia>
      </inertial>
      <collision name='front_left_wheel_link_collision'>
        <pose>0 0 0 1.5708 0 1.5708</pose>
        <geometry>
          <cylinder>
            <length>0.042</length>
            <radius>0.08</radius>
          </cylinder>
        </geometry>
        <surface>
          <contact>
            <ode/>
          </contact>
          <friction>
            <ode>
              <mu>0.01</mu>
              <mu2>0.01</mu2>
            </ode>
          </friction>
        </surface>
      </collision>
      <visual name='front_left_wheel_link_visual'>
        <pose>0 0 0 0 -0 0</pose>
        <geometry>
          <mesh>
            <scale>0.001 0.001 0.001</scale>
            <uri>model://amr/meshes/Mecanum_Left.stl</uri>
          </mesh>
        </geometry>
        <material>
          <ambient>0.1764 0.4588 0.8509 1</ambient>
          <diffuse>0.1764 0.4588 0.8509 1</diffuse>
          <specular>0.1764 0.4588 0.8509 1</specular>
          <emissive>0 0 0 0</emissive>
        </material>
      </visual>
    </link>
    <joint name='front_right_wheel_joint' type='revolute'>
      <pose relative_to='base_footprint'>0.265 0.28 0 0 0 0</pose>
      <parent>base_footprint</parent>
      <child>front_right_wheel_link</child>
      <axis>
        <xyz>0 1 0</xyz>
        <limit>
          <lower>-1e+16</lower>
          <upper>1e+16</upper>
        </limit>
        <dynamics>
          <spring_reference>0</spring_reference>
          <spring_stiffness>0</spring_stiffness>
        </dynamics>
      </axis>
    </joint>
    <link name='front_right_wheel_link'>
      <pose relative_to='front_right_wheel_joint'>0 0 0 0 0 0</pose>
      <inertial>
        <pose>0 0 0 0 -0 0</pose>
        <mass>1</mass>
        <inertia>
          <ixx>0.01024</ixx>
          <ixy>0</ixy>
          <ixz>0</ixz>
          <iyy>0.01024</iyy>
          <iyz>0</iyz>
          <izz>0.01024</izz>
        </inertia>
      </inertial>
      <collision name='front_right_wheel_link_collision'>
        <pose>0 0 0 1.5708 0 1.5708</pose>
        <geometry>
          <cylinder>
            <length>0.042</length>
            <radius>0.08</radius>
          </cylinder>
        </geometry>
        <surface>
          <contact>
            <ode/>
          </contact>
          <friction>
            <ode>
              <mu>0.01</mu>
              <mu2>0.01</mu2>
            </ode>
          </friction>
        </surface>
      </collision>
      <visual name='front_right_wheel_link_visual'>
        <pose>0 0 0 0 -0 0</pose>
        <geometry>
          <mesh>
            <scale>0.001 0.001 0.001</scale>
            <uri>model://amr/meshes/Mecanum_Right.stl</uri>
          </mesh>
        </geometry>
        <material>
          <ambient>0.1764 0.4588 0.8509 1</ambient>
          <diffuse>0.1764 0.4588 0.8509 1</diffuse>
          <specular>0.1764 0.4588 0.8509 1</specular>
          <emissive>0 0 0 0</emissive>
        </material>
      </visual>
    </link>
    <joint name='rear_left_wheel_joint' type='revolute'>
      <pose relative_to='base_footprint'>-0.265 -0.28 0 0 0 0</pose>
      <parent>base_footprint</parent>
      <child>rear_left_wheel_link</child>
      <axis>
        <xyz>0 1 0</xyz>
        <limit>
          <lower>-1e+16</lower>
          <upper>1e+16</upper>
        </limit>
        <dynamics>
          <spring_reference>0</spring_reference>
          <spring_stiffness>0</spring_stiffness>
        </dynamics>
      </axis>
    </joint>
    <link name='rear_left_wheel_link'>
      <pose relative_to='rear_left_wheel_joint'>0 0 0 0 0 0</pose>
      <inertial>
        <pose>0 0 0 0 -0 0</pose>
        <mass>1</mass>
        <inertia>
          <ixx>0.01024</ixx>
          <ixy>0</ixy>
          <ixz>0</ixz>
          <iyy>0.01024</iyy>
          <iyz>0</iyz>
          <izz>0.01024</izz>
        </inertia>
      </inertial>
      <collision name='rear_left_wheel_link_collision'>
        <pose>0 0 0 1.5708 0 1.5708</pose>
        <geometry>
          <cylinder>
            <length>0.042</length>
            <radius>0.08</radius>
          </cylinder>
        </geometry>
        <surface>
          <contact>
            <ode/>
          </contact>
          <friction>
            <ode>
              <mu>0.01</mu>
              <mu2>0.01</mu2>
            </ode>
          </friction>
        </surface>
      </collision>
      <visual name='rear_left_wheel_link_visual'>
        <pose>0 0 0 0 -0 0</pose>
        <geometry>
          <mesh>
            <scale>0.001 0.001 0.001</scale>
            <uri>model://amr/meshes/Mecanum_Left.stl</uri>
          </mesh>
        </geometry>
        <material>
          <ambient>0.1764 0.4588 0.8509 1</ambient>
          <diffuse>0.1764 0.4588 0.8509 1</diffuse>
          <specular>0.1764 0.4588 0.8509 1</specular>
          <emissive>0 0 0 0</emissive>
        </material>
      </visual>
    </link>
    <joint name='rear_right_wheel_joint' type='revolute'>
      <pose relative_to='base_footprint'>0.265 -0.28 0 0 0 0</pose>
      <parent>base_footprint</parent>
      <child>rear_right_wheel_link</child>
      <axis>
        <xyz>0 1 0</xyz>
        <limit>
          <lower>-1e+16</lower>
          <upper>1e+16</upper>
        </limit>
        <dynamics>
          <spring_reference>0</spring_reference>
          <spring_stiffness>0</spring_stiffness>
        </dynamics>
      </axis>
    </joint>
    <link name='rear_right_wheel_link'>
      <pose relative_to='rear_right_wheel_joint'>0 0 0 0 0 0</pose>
      <inertial>
        <pose>0 0 0 0 -0 0</pose>
        <mass>1</mass>
        <inertia>
          <ixx>0.01024</ixx>
          <ixy>0</ixy>
          <ixz>0</ixz>
          <iyy>0.01024</iyy>
          <iyz>0</iyz>
          <izz>0.01024</izz>
        </inertia>
      </inertial>
      <collision name='rear_right_wheel_link_collision'>
        <pose>0 0 0 1.5708 -0 1.5708</pose>
        <geometry>
          <cylinder>
            <length>0.042</length>
            <radius>0.08</radius>
          </cylinder>
        </geometry>
        <surface>
          <contact>
            <ode/>
          </contact>
          <friction>
            <ode>
              <mu>0.01</mu>
              <mu2>0.01</mu2>
            </ode>
          </friction>
        </surface>
      </collision>
      <visual name='rear_right_wheel_link_visual'>
        <pose>0 0 0 0 -0 0</pose>
        <geometry>
          <mesh>
            <scale>0.001 0.001 0.001</scale>
            <uri>model://amr/meshes/Mecanum_Right.stl</uri>
          </mesh>
        </geometry>
        <material>
          <ambient>0.1764 0.4588 0.8509 1</ambient>
          <diffuse>0.1764 0.4588 0.8509 1</diffuse>
          <specular>0.1764 0.4588 0.8509 1</specular>
          <emissive>0 0 0 0</emissive>
        </material>
      </visual>
    </link>
    <static>0</static>
    <plugin name='omni_directional_movement_controller' filename='libgazebo_ros_planar_move.so'>
      <ros>
        <argument>odom:=odom</argument>
      </ros>
      <commandTopic>cmd_vel</commandTopic>
      <odometryTopic>odom</odometryTopic>
      <odometryFrame>odom</odometryFrame>
      <odometry_rate>20.0</odometry_rate>
      <robot_base_frame>base_footprint</robot_base_frame>
      <publish_odom>1</publish_odom>
      <publish_odom_tf>0</publish_odom_tf>
      <odometry_source>1</odometry_source>
    </plugin>
  </model>
</sdf>
