<?xml version="1.0" ?>
<!-- =================================================================================== -->
<!-- |    This document was autogenerated by xacro from amr.urdf                       | -->
<!-- |    EDITING THIS FILE BY HAND IS NOT RECOMMENDED                                 | -->
<!-- =================================================================================== -->
<robot name="amr">
  <material name="silver">
    <color rgba="0.7 0.7 0.7 1.0"/>
  </material>
  <link name="base_footprint"/>
  <link name="base_link">
    <visual>
      <origin rpy="0.0 0.0 0.0" xyz="0.0 0.0 0.0"/>
      <geometry>
        <mesh filename="package://amr_sim_pkg/meshes/base_link.stl" scale="1 1 1"/>
      </geometry>
      <material name="silver"/>
    </visual>
    <collision>
      <origin rpy="0 0 0" xyz="0 0 0"/>
      <geometry>
        <mesh filename="package://amr_sim_pkg/meshes/base_link.stl" scale="1 1 1"/>
      </geometry>
    </collision>
    <inertial>
      <origin rpy="0.0 0.0 0.0" xyz="0.0 0.0 0.0"/>
      <mass value="118.02415513468259"/>
      <inertia ixx="11.552282" ixy="-0.006658" ixz="0.0" iyy="4.683005" iyz="0.0" izz="15.747905"/>
    </inertial>
  </link>
  <joint name="base_to_footprint" type="fixed">
    <parent link="base_footprint"/>
    <child link="base_link"/>
    <origin rpy="0 0 0" xyz="0 0 0"/>
  </joint>
  <link name="front_left_wheel_link">
    <visual>
      <origin rpy="0.0 0.0 0.0" xyz="0.0 0.0 0.0"/>
      <geometry>
        <mesh filename="package://amr_sim_pkg/meshes/Mecanum_Left.stl" scale="0.001 0.001 0.001"/>
      </geometry>
      <material name="blue">
        <color rgba="0.1764 0.4588 0.8509 1.0"/>
      </material>
    </visual>
    <collision>
      <origin rpy="1.5707963267948966 0 1.5707963267948966" xyz="0 0 0"/>
      <geometry>
        <cylinder length="0.042" radius="0.08"/>
      </geometry>
    </collision>
    <inertial>
      <origin rpy="0.0 0.0 0.0" xyz="0.0 0.0 0.0"/>
      <mass value="1"/>
      <inertia ixx="0.00256" ixy="0" ixz="0" iyy="0.00256" iyz="0" izz="0.00256"/>
    </inertial>
  </link>
  <gazebo reference="front_left_wheel_link">
    <mu1>0.01</mu1>
    <mu2>0.01</mu2>
  </gazebo>
  <gazebo reference="front_left_wheel_link">
    <visual>
      <material>
        <ambient>0.1764 0.4588 0.8509 1.0</ambient>
        <diffuse>0.1764 0.4588 0.8509 1.0</diffuse>
        <specular>0.1764 0.4588 0.8509 1.0</specular>
        <emissive>0.0 0.0 0.0 0.0</emissive>
      </material>
    </visual>
  </gazebo>
  <joint name="front_left_wheel_joint" type="continuous">
    <axis xyz="0.0 1.0 0.0"/>
    <parent link="base_link"/>
    <child link="front_left_wheel_link"/>
    <origin rpy="0 0 0" xyz="-0.265 0.28 0"/>
  </joint>
  <link name="rear_left_wheel_link">
    <visual>
      <origin rpy="0.0 0.0 0.0" xyz="0.0 0.0 0.0"/>
      <geometry>
        <mesh filename="package://amr_sim_pkg/meshes/Mecanum_Left.stl" scale="0.001 0.001 0.001"/>
      </geometry>
      <material name="blue">
        <color rgba="0.1764 0.4588 0.8509 1.0"/>
      </material>
    </visual>
    <collision>
      <origin rpy="1.5707963267948966 0 1.5707963267948966" xyz="0 0 0"/>
      <geometry>
        <cylinder length="0.042" radius="0.08"/>
      </geometry>
    </collision>
    <inertial>
      <origin rpy="0.0 0.0 0.0" xyz="0.0 0.0 0.0"/>
      <mass value="1"/>
      <inertia ixx="0.00256" ixy="0" ixz="0" iyy="0.00256" iyz="0" izz="0.00256"/>
    </inertial>
  </link>
  <gazebo reference="rear_left_wheel_link">
    <mu1>0.01</mu1>
    <mu2>0.01</mu2>
  </gazebo>
  <gazebo reference="rear_left_wheel_link">
    <visual>
      <material>
        <ambient>0.1764 0.4588 0.8509 1.0</ambient>
        <diffuse>0.1764 0.4588 0.8509 1.0</diffuse>
        <specular>0.1764 0.4588 0.8509 1.0</specular>
        <emissive>0.0 0.0 0.0 0.0</emissive>
      </material>
    </visual>
  </gazebo>
  <joint name="rear_left_wheel_joint" type="continuous">
    <axis xyz="0.0 1.0 0.0"/>
    <parent link="base_link"/>
    <child link="rear_left_wheel_link"/>
    <origin rpy="0 0 0" xyz="-0.265 -0.28 0"/>
  </joint>
  <link name="front_right_wheel_link">
    <visual>
      <origin rpy="0.0 0.0 0.0" xyz="0.0 0.0 0.0"/>
      <geometry>
        <mesh filename="package://amr_sim_pkg/meshes/Mecanum_Right.stl" scale="0.001 0.001 0.001"/>
      </geometry>
      <material name="blue">
        <color rgba="0.1764 0.4588 0.8509 1.0"/>
      </material>
    </visual>
    <collision>
      <origin rpy="1.5707963267948966 0 1.5707963267948966" xyz="0 0 0"/>
      <geometry>
        <cylinder length="0.042" radius="0.08"/>
      </geometry>
    </collision>
    <inertial>
      <origin rpy="0.0 0.0 0.0" xyz="0.0 0.0 0.0"/>
      <mass value="1"/>
      <inertia ixx="0.00256" ixy="0" ixz="0" iyy="0.00256" iyz="0" izz="0.00256"/>
    </inertial>
  </link>
  <gazebo reference="front_right_wheel_link">
    <mu1>0.01</mu1>
    <mu2>0.01</mu2>
  </gazebo>
  <gazebo reference="front_right_wheel_link">
    <visual>
      <material>
        <ambient>0.1764 0.4588 0.8509 1.0</ambient>
        <diffuse>0.1764 0.4588 0.8509 1.0</diffuse>
        <specular>0.1764 0.4588 0.8509 1.0</specular>
        <emissive>0.0 0.0 0.0 0.0</emissive>
      </material>
    </visual>
  </gazebo>
  <joint name="front_right_wheel_joint" type="continuous">
    <axis xyz="0.0 1.0 0.0"/>
    <parent link="base_link"/>
    <child link="front_right_wheel_link"/>
    <origin rpy="0 0 0" xyz="0.265 0.28 0"/>
  </joint>
  <link name="rear_right_wheel_link">
    <visual>
      <origin rpy="0.0 0.0 0.0" xyz="0.0 0.0 0.0"/>
      <geometry>
        <mesh filename="package://amr_sim_pkg/meshes/Mecanum_Right.stl" scale="0.001 0.001 0.001"/>
      </geometry>
      <material name="blue">
        <color rgba="0.1764 0.4588 0.8509 1.0"/>
      </material>
    </visual>
    <collision>
      <origin rpy="1.5707963267948966 0 1.5707963267948966" xyz="0 0 0"/>
      <geometry>
        <cylinder length="0.042" radius="0.08"/>
      </geometry>
    </collision>
    <inertial>
      <origin rpy="0.0 0.0 0.0" xyz="0.0 0.0 0.0"/>
      <mass value="1"/>
      <inertia ixx="0.00256" ixy="0" ixz="0" iyy="0.00256" iyz="0" izz="0.00256"/>
    </inertial>
  </link>
  <gazebo reference="rear_right_wheel_link">
    <mu1>0.01</mu1>
    <mu2>0.01</mu2>
  </gazebo>
  <gazebo reference="rear_right_wheel_link">
    <visual>
      <material>
        <ambient>0.1764 0.4588 0.8509 1.0</ambient>
        <diffuse>0.1764 0.4588 0.8509 1.0</diffuse>
        <specular>0.1764 0.4588 0.8509 1.0</specular>
        <emissive>0.0 0.0 0.0 0.0</emissive>
      </material>
    </visual>
  </gazebo>
  <joint name="rear_right_wheel_joint" type="continuous">
    <axis xyz="0.0 1.0 0.0"/>
    <parent link="base_link"/>
    <child link="rear_right_wheel_link"/>
    <origin rpy="0 0 0" xyz="0.265 -0.28 0"/>
  </joint>
  <link name="laser_link">
    <visual>
      <origin rpy="0.0 0.0 0.0" xyz="0.0 0.0 0.0"/>
      <geometry>
        <mesh filename="package://amr_sim_pkg/meshes/rpi_lidar_1.stl" scale="1 1 1"/>
      </geometry>
      <material name="black">
        <color rgba="0 0 0 1.0"/>
      </material>
    </visual>
    <collision>
      <origin rpy="0.0 0.0 0.0" xyz="0.0 0.0 0.0"/>
      <geometry>
        <mesh filename="package://amr_sim_pkg/meshes/rpi_lidar_1.stl" scale="1 1 1"/>
      </geometry>
    </collision>
    <inertial>
      <origin rpy="0 0 0" xyz="0 0 0"/>
      <mass value="0.1"/>
      <inertia ixx="5.625000000000001e-05" ixy="0" ixz="0" iyy="5.625000000000001e-05" iyz="0" izz="5.625000000000001e-05"/>
    </inertial>
  </link>
  <gazebo reference="laser_link">
    <visual>
      <material>
        <ambient>0 0 0 1.0</ambient>
        <diffuse>0 0 0 1.0</diffuse>
        <specular>0 0 0 1.0</specular>
        <emissive>0.0 0.0 0.0 0.0</emissive>
      </material>
    </visual>
  </gazebo>
  <joint name="lidar_joint" type="fixed">
    <parent link="base_link"/>
    <child link="laser_link"/>
    <origin rpy="0 0 0" xyz="0.0 0.0 0.125"/>
  </joint>
  <gazebo reference="laser_link">
    <sensor name="laser_link_head_hokuyo_sensor" type="ray">
      <always_on>true</always_on>
      <update_rate>10</update_rate>
      <pose>0 0 0 0 0 0</pose>
      <visualize>true</visualize>
      <ray>
        <scan>
          <horizontal>
            <samples>360</samples>
            <resolution>1</resolution>
            <min_angle>-3.1416</min_angle>
            <max_angle>3.1416</max_angle>
          </horizontal>
        </scan>
        <range>
          <min>0.21</min>
          <max>5.5</max>
          <resolution>0.01</resolution>
        </range>
      </ray>
      <plugin filename="libgazebo_ros_ray_sensor.so" name="laser_link_gazebo_ros_head_hokuyo_controller">
        <ros>
          <remapping>~/out:=scan</remapping>
        </ros>
        <output_type>sensor_msgs/LaserScan</output_type>
        <alwaysOn>true</alwaysOn>
        <updateRate>10</updateRate>
        <topicName>scan</topicName>
        <frame_name>laser_link</frame_name>
        <output_type>sensor_msgs/LaserScan</output_type>
      </plugin>
    </sensor>
  </gazebo>
  <link name="imu_link"/>
  <joint name="imu_joint" type="fixed">
    <parent link="base_link"/>
    <child link="imu_link"/>
    <origin rpy="0.0 0.0 0.0" xyz="0.0 0.0 0.0"/>
  </joint>
  <gazebo reference="imu_link">
    <gravity>true</gravity>
    <sensor name="imu_sensor" type="imu"/>
    <always_on>true</always_on>
    <update_rate>100</update_rate>
    <visualize>true</visualize>
    <topic>__default_topic__</topic>
    <plugin filename="libgazebo_ros_imu_sensor.so" name="imu_plugin">
      <ros>
        <remapping>~/out:=imu/data</remapping>
      </ros>
      <topicName>imu/data</topicName>
      <bodyName>imu_link</bodyName>
      <updateRateHZ>10.0</updateRateHZ>
      <gaussianNoise>0.0</gaussianNoise>
      <xyzOffset>0 0 0</xyzOffset>
      <rpyOffset>0 0 0</rpyOffset>
      <frameName>imu_link</frameName>
      <initialOrientationAsReference>false</initialOrientationAsReference>
    </plugin>
    <pose>0 0 0 0 0 0</pose>
  </gazebo>
  <gazebo>
    <plugin filename="libgazebo_ros_planar_move.so" name="omni_directional_movement_controller">
      <ros>
        <argument>odom:=odom</argument>
      </ros>
      <commandTopic>cmd_vel</commandTopic>
      <odometryTopic>odom</odometryTopic>
      <odometryFrame>odom</odometryFrame>
      <odometry_rate>20.0</odometry_rate>
      <robot_base_frame>base_footprint</robot_base_frame>
      <publish_odom>true</publish_odom>
      <publish_odom_tf>false</publish_odom_tf>
      <odometry_source>1</odometry_source>
    </plugin>
  </gazebo>
</robot>
